<mujoco model="simple_sea_test">
  <compiler angle="radian"/>
  <option timestep="0.002"/>
  <visual>
    <headlight diffuse="0.6 0.6 0.6" ambient="0.3 0.3 0.3" specular="0 0 0"/>
    <rgba haze="0.15 0.25 0.35 1"/>
    <global azimuth="0" elevation="-20"/>
  </visual>
  <asset>
    <texture type="skybox" builtin="gradient" rgb1="0.3 0.5 0.7" rgb2="0 0 0" width="512" height="3072"/>
    <texture type="2d" name="groundplane" builtin="checker" mark="edge" rgb1="0.2 0.3 0.4" rgb2="0.1 0.2 0.3"
      markrgb="0.8 0.8 0.8" width="300" height="300"/>
    <material name="groundplane" texture="groundplane" texuniform="true" texrepeat="5 5" reflectance="0.2"/>
  </asset>
  <worldbody>
    <light pos="0 0 1.5" dir="0 0 -1" directional="true"/>
    <geom name="floor" size="0 0 0.05" type="plane" material="groundplane"/>
    <body name="motor_side" pos="0 0 0.5">
      <joint name="theta" type="hinge" axis="0 1 0" actuatorfrcrange="-6.28 6.28" damping="1.0" range="-6.28 6.28"/>
      <geom type="box" size="0.05 0.02 0.05" rgba="1 0 0 0.5"/>
      <body name="link_side" pos="0 0.04 0">
        <joint name="q" type="hinge" axis="0 1 0" stiffness="1.0" damping="1.0" range="-6.28 6.28"/>
        <geom type="box" size="0.15 0.02 0.02" pos="0.15 0 0" rgba="0 1 0 0.5"/>
        <body name="end_effector" pos="0.3 0 0">
          <geom type="sphere" size="0.03" rgba="0 0 1 1"/>
        </body>
      </body>
    </body>
  </worldbody>
  <actuator>
    <position name="motor" joint="theta" ctrlrange="-5 5" gear="1"/>
  </actuator>
</mujoco>