<?xml version="1.0" ?>
<!-- =================================================================================== -->
<!-- |    This document was autogenerated by xacro from leg_constrained.xacro          | -->
<!-- |    EDITING THIS FILE BY HAND IS NOT RECOMMENDED                                 | -->
<!-- =================================================================================== -->
<robot name="leg_constrained">

<mujoco>
  <compiler meshdir="assets" discardvisual="false" fusestatic="false"/>
</mujoco>

  <!-- NEW !!! LEG_CONSTRAINED -->
  <!-- CART MESHES -->
  <material name="black">
    <color rgba="0.0 0.0 0.0 1.0"/>
  </material>
  <material name="blue">
    <color rgba="0.0 0.0 0.8 1.0"/>
  </material>
  <material name="green">
    <color rgba="0.0 0.8 0.0 1.0"/>
  </material>
  <material name="grey">
    <color rgba="0.2 0.2 0.2 1.0"/>
  </material>
  <material name="orange">
    <color rgba="1.0 0.4235294117647059 0.0392156862745098 0.5"/>
  </material>
  <material name="brown">
    <color rgba="0.8705882352941177 0.8117647058823529 0.7647058823529411 1.0"/>
  </material>
  <material name="red">
    <color rgba="0.8 0.0 0.0 1.0"/>
  </material>
  <material name="white">
    <color rgba="1.0 1.0 1.0 1.0"/>
  </material>

  <!-- CART MESHES -->
  <!-- -1) World Link -->
  <link name="world"/>
  <joint name="rootJoint" type="fixed">
    <origin rpy="0. 0. 0." xyz="0. 0. 0."/>
    <parent link="world"/>
    <child link="base_link"/>
  </joint>
  <link name="base_link">
    <visual>
      <material name="white"/>
      <origin rpy="0. 0. -3.141592" xyz="0. 0. 0."/>
      <geometry>
        <mesh filename="file://${path_to_stl}cart.stl" scale="0.001 0.001 0.001"/>
      </geometry>
    </visual>
    <inertial>
      <mass value="1e-4"/>
      <inertia ixx="1e-5" ixy="0." ixz="0." iyy="1e-5" iyz="0." izz="1e-5"/>
      <origin rpy="0. 0. 0." xyz="0. 0. 0."/>
    </inertial>
  </link>
  <!-- Joint to fix the leg to the base -->
  <joint name="LH_HAA" type="fixed">
    <parent link="base_link"/>
    <child link="LH_SHOULDER"/>
    <origin rpy="0 3.141592 1.570796" xyz="0.025 0.05 0.5"/>
    <axis xyz="0 0 -1"/>
    <limit effort="50000." lower="0.0" upper="1.0" velocity="10000"/>
  </joint>
  <!-- Shoulder link -->
  <link name="LH_SHOULDER">
    <visual>
      <material name="white"/>
      <geometry>
        <mesh filename="file://${path_to_stl}Module_left_hind.stl"/>
      </geometry>
    </visual>
    <collision>
      <origin rpy="0 0 0" xyz="-0.0945 0 0"/>
      <geometry>
        <box size="0.269 0.057 0.060"/>
      </geometry>
    </collision>
    <inertial>
      <mass value="0.47669673"/>
      <origin rpy="0 0 0" xyz="-7.2487360e-02 3.1582591e-02 2.4812434e-03"/>
      <inertia ixx="2.1574269e-04" ixy="3.3437484e-05" ixz="-2.4284668e-06" iyy="3.0607390e-03" iyz="-2.0388977e-06" izz="3.0504273e-03"/>
    </inertial>
  </link>

  <!-- Hip joint -->
  <joint name="LH_HFE" type="revolute">
    <parent link="LH_SHOULDER"/>
    <child link="LH_UPPER_LEG"/>
    <origin rpy="0 1.570796 0" xyz="-0.19 0.044 0"/>
    <axis xyz="0 1 0"/>
    <limit effort="5.0" lower="-3.141592" upper="3.141592" velocity="1000"/>
  </joint>
  <!-- Upper leg link -->
  <link name="LH_UPPER_LEG">
    <visual>
      <material name="white"/>
      <origin rpy="0 0 0" xyz="0 0 0"/>
      <geometry>
        <mesh filename="file://${path_to_stl}Module_left_hind.stl"/>
      </geometry>
    </visual>
    <collision>
      <origin rpy="0 0 0" xyz="-0.0945 0.015 0"/>
      <geometry>
        <box size="0.269 0.057 0.060"/>
      </geometry>
    </collision>
    <inertial>
      <mass value="0.47669673"/>
      <origin rpy="0 0 0" xyz="-7.2487360e-02 3.1582591e-02 2.4812434e-03"/>
      <inertia ixx="2.1574269e-04" ixy="3.3437484e-05" ixz="-2.4284668e-06" iyy="3.0607390e-03" iyz="-2.0388977e-06" izz="3.0504273e-03"/>
    </inertial>
  </link>

  <!-- Knee joint -->
  <joint name="LH_KFE" type="revolute">
    <parent link="LH_UPPER_LEG"/>
    <child link="LH_LOWER_LEG"/>
    <origin rpy="0 0 0" xyz="-0.19 0.044 0"/>
    <axis xyz="0 1 0"/>
    <limit effort="5.0" lower="-3.141592" upper="3.141592" velocity="1000"/>
  </joint>
  <!-- Lower leg link -->
  <link name="LH_LOWER_LEG">
    <visual>
      <material name="white"/>
      <origin rpy="0 1.570796 0" xyz="0 0 0"/>
      <geometry>
        <mesh filename="file://${path_to_stl}Lower_leg_left.stl"/>
      </geometry>
    </visual>
    <collision>
      <origin rpy="0 1.570796 0" xyz="0 0 0"/>
      <geometry>
        <box size="0.269 0.057 0.060"/>
      </geometry>
    </collision>
    <inertial>
      <mass value="0.046942"/>
      <origin rpy="0 0 0" xyz="-0.0660893 0.0198901 1.552593e-05"/>
      <inertia ixx="5.140780e-06" ixy="-1.089102e-05" ixz="2.46811e-08" iyy="0.0002124295" iyz="-2.702972e-09" izz="0.0002115478"/>
    </inertial>
  </link>
  
  <!-- Normal feet -->
  <joint name="LH_ANKLE" type="fixed">
    <parent link="LH_LOWER_LEG"/>
    <child link="LH_FOOT"/>
    <origin rpy="0 0 0" xyz="-0.19 0.028 0"/>
  </joint>
  <!-- FOOT LINK -->
  <link name="LH_FOOT">
  </link>
</robot>
